14:11:33.951 INFO Test execution started: search_test
14:11:33.951 INFO Browser: chrome
14:11:33.952 INFO Using data: 
    url: 'www.tentrr.com/s/sites/'
    search_value: 'Frog Pond'
    expected_value: 'Frog Pond'

14:11:36.003 INFO Take screenshot error
14:11:36.717 INFO error__e7b8edfc
14:11:36.717 ERROR An error ocurred:
Traceback (most recent call last):
  File "/Library/Frameworks/Python.framework/Versions/3.6/lib/python3.6/site-packages/golem_framework-0.5.0-py3.6.egg/golem/test_runner/test_runner.py", line 122, in run_test
    test_module.test(execution.data)
  File "/Users/yidong/golem/tentrr/projects/Tentrr/tests/search_test.py", line 7, in test
    navigate(data.url)
  File "/Library/Frameworks/Python.framework/Versions/3.6/lib/python3.6/site-packages/golem_framework-0.5.0-py3.6.egg/golem/actions.py", line 338, in navigate
    driver.get(url)
  File "/Library/Frameworks/Python.framework/Versions/3.6/lib/python3.6/site-packages/selenium-3.14.0-py3.6.egg/selenium/webdriver/remote/webdriver.py", line 332, in get
    self.execute(Command.GET, {'url': url})
  File "/Library/Frameworks/Python.framework/Versions/3.6/lib/python3.6/site-packages/selenium-3.14.0-py3.6.egg/selenium/webdriver/remote/webdriver.py", line 320, in execute
    self.error_handler.check_response(response)
  File "/Library/Frameworks/Python.framework/Versions/3.6/lib/python3.6/site-packages/selenium-3.14.0-py3.6.egg/selenium/webdriver/remote/errorhandler.py", line 242, in check_response
    raise exception_class(message, screen, stacktrace)
selenium.common.exceptions.WebDriverException: Message: unknown error: unhandled inspector error: {"code":-32000,"message":"Cannot navigate to invalid URL"}
  (Session info: chrome=68.0.3440.106)
  (Driver info: chromedriver=2.41.578706 (5f725d1b4f0a4acbf5259df887244095596231db),platform=Mac OS X 10.13.0 x86_64)

14:11:36.718 INFO Close driver
